 * Serving Flask app 'app'
 * Debug mode: on
[31m[1mWARNING: This is a development server. Do not use it in a production deployment. Use a production WSGI server instead.[0m
 * Running on http://127.0.0.1:5000
[33mPress CTRL+C to quit[0m
 * Restarting with stat
 * Debugger is active!
 * Debugger PIN: 514-421-982
127.0.0.1 - - [16/Jun/2025 22:45:35] "[35m[1mGET / HTTP/1.1[0m" 500 -
Traceback (most recent call last):
  File "/home/pablo/Desktop/Honeypot/cowrie/cowrie-env/lib/python3.13/site-packages/urllib3/connectionpool.py", line 787, in urlopen
    response = self._make_request(
    
  File "/home/pablo/Desktop/Honeypot/cowrie/cowrie-env/lib/python3.13/site-packages/urllib3/connectionpool.py", line 534, in _make_request
    response = conn.getresponse()
  File "/home/pablo/Desktop/Honeypot/cowrie/cowrie-env/lib/python3.13/site-packages/urllib3/connection.py", line 516, in getresponse
    httplib_response = super().getresponse()
  File "/usr/lib/python3.13/http/client.py", line 1430, in getresponse
    response.begin()
    ~~~~~~~~~~~~~~^^
  File "/usr/lib/python3.13/http/client.py", line 331, in begin
    version, status, reason = self._read_status()
                              ~~~~~~~~~~~~~~~~~^^
  File "/usr/lib/python3.13/http/client.py", line 300, in _read_status
    raise RemoteDisconnected("Remote end closed connection without"
    ^^^^^^^^^^^^^^^^^^^^^^^^^^^^^^^^^^^^^
http.client.RemoteDisconnected: Remote end closed connection without response

During handling of the above exception, another exception occurred:

Traceback (most recent call last):
  File "/home/pablo/Desktop/Honeypot/cowrie/cowrie-env/lib/python3.13/site-packages/elastic_transport/_node/_http_urllib3.py", line 167, in perform_request
    response = self.pool.urlopen(
    
  File "/home/pablo/Desktop/Honeypot/cowrie/cowrie-env/lib/python3.13/site-packages/urllib3/connectionpool.py", line 841, in urlopen
    retries = retries.increment(
    
  File "/home/pablo/Desktop/Honeypot/cowrie/cowrie-env/lib/python3.13/site-packages/urllib3/util/retry.py", line 449, in increment
    raise reraise(type(error), error, _stacktrace)
          ~~~~~~~^^^^^^^^^^^^^^^^^^^^^^^^^^^^^^^^^
  File "/home/pablo/Desktop/Honeypot/cowrie/cowrie-env/lib/python3.13/site-packages/urllib3/util/util.py", line 38, in reraise
    raise value.with_traceback(tb)
  File "/home/pablo/Desktop/Honeypot/cowrie/cowrie-env/lib/python3.13/site-packages/urllib3/connectionpool.py", line 787, in urlopen
    response = self._make_request(
    
  File "/home/pablo/Desktop/Honeypot/cowrie/cowrie-env/lib/python3.13/site-packages/urllib3/connectionpool.py", line 534, in _make_request
    response = conn.getresponse()
  File "/home/pablo/Desktop/Honeypot/cowrie/cowrie-env/lib/python3.13/site-packages/urllib3/connection.py", line 516, in getresponse
    httplib_response = super().getresponse()
  File "/usr/lib/python3.13/http/client.py", line 1430, in getresponse
    response.begin()
    ~~~~~~~~~~~~~~^^
  File "/usr/lib/python3.13/http/client.py", line 331, in begin
    version, status, reason = self._read_status()
                              ~~~~~~~~~~~~~~~~~^^
  File "/usr/lib/python3.13/http/client.py", line 300, in _read_status
    raise RemoteDisconnected("Remote end closed connection without"
    ^^^^^^^^^^^^^^^^^^^^^^^^^^^^^^^^^^^^^
urllib3.exceptions.ProtocolError: ('Connection aborted.', RemoteDisconnected('Remote end closed connection without response'))

The above exception was the direct cause of the following exception:

Traceback (most recent call last):
  File "/home/pablo/Desktop/Honeypot/cowrie/cowrie-env/lib/python3.13/site-packages/flask/app.py", line 1536, in __call__
    return self.wsgi_app(environ, start_response)
           ~~~~~~~~~~~~~^^^^^^^^^^^^^^^^^^^^^^^^^
  File "/home/pablo/Desktop/Honeypot/cowrie/cowrie-env/lib/python3.13/site-packages/flask/app.py", line 1514, in wsgi_app
    response = self.handle_exception(e)
  File "/home/pablo/Desktop/Honeypot/cowrie/cowrie-env/lib/python3.13/site-packages/flask/app.py", line 1511, in wsgi_app
    response = self.full_dispatch_request()
  File "/home/pablo/Desktop/Honeypot/cowrie/cowrie-env/lib/python3.13/site-packages/flask/app.py", line 919, in full_dispatch_request
    rv = self.handle_user_exception(e)
  File "/home/pablo/Desktop/Honeypot/cowrie/cowrie-env/lib/python3.13/site-packages/flask/app.py", line 917, in full_dispatch_request
    rv = self.dispatch_request()
  File "/home/pablo/Desktop/Honeypot/cowrie/cowrie-env/lib/python3.13/site-packages/flask/app.py", line 902, in dispatch_request
    return self.ensure_sync(self.view_functions[rule.endpoint])(**view_args)  # type: ignore[no-any-return]
           ~~~~~~~~~~~~~~~~~~~~~~~~~~~~~~~~~~~~~~~~~~~~~~~~~~~~^^^^^^^^^^^^^
  File "/home/pablo/Desktop/Honeypot/app.py", line 9, in dashboard
    res = es.search(index="cowrie-attacks", size=1000)
  File "/home/pablo/Desktop/Honeypot/cowrie/cowrie-env/lib/python3.13/site-packages/elasticsearch/_sync/client/utils.py", line 415, in wrapped
    return api(*args, **kwargs)
  File "/home/pablo/Desktop/Honeypot/cowrie/cowrie-env/lib/python3.13/site-packages/elasticsearch/_sync/client/__init__.py", line 4916, in search
    return self.perform_request(  # type: ignore[return-value]
    
  File "/home/pablo/Desktop/Honeypot/cowrie/cowrie-env/lib/python3.13/site-packages/elasticsearch/_sync/client/_base.py", line 271, in perform_request
    response = self._perform_request(
    
  File "/home/pablo/Desktop/Honeypot/cowrie/cowrie-env/lib/python3.13/site-packages/elasticsearch/_sync/client/_base.py", line 315, in _perform_request
    meta, resp_body = self.transport.perform_request(
    
  File "/home/pablo/Desktop/Honeypot/cowrie/cowrie-env/lib/python3.13/site-packages/elastic_transport/_transport.py", line 342, in perform_request
    resp = node.perform_request(
    
  File "/home/pablo/Desktop/Honeypot/cowrie/cowrie-env/lib/python3.13/site-packages/elastic_transport/_node/_http_urllib3.py", line 202, in perform_request
    raise err from e
elastic_transport.ConnectionError: Connection error caused by: ConnectionError(Connection error caused by: ProtocolError(('Connection aborted.', RemoteDisconnected('Remote end closed connection without response'))))
127.0.0.1 - - [16/Jun/2025 22:45:35] "GET /?__debugger__=yes&cmd=resource&f=debugger.js HTTP/1.1" 200 -
127.0.0.1 - - [16/Jun/2025 22:45:35] "GET /?__debugger__=yes&cmd=resource&f=style.css HTTP/1.1" 200 -
127.0.0.1 - - [16/Jun/2025 22:45:35] "GET /?__debugger__=yes&cmd=resource&f=console.png HTTP/1.1" 200 -
127.0.0.1 - - [16/Jun/2025 22:45:35] "GET /?__debugger__=yes&cmd=resource&f=console.png&s=Wc3a4sQDFX5eIEJRicrM HTTP/1.1" 200 -
 * Serving Flask app 'app'
 * Debug mode: on
[31m[1mWARNING: This is a development server. Do not use it in a production deployment. Use a production WSGI server instead.[0m
 * Running on http://127.0.0.1:5000
[33mPress CTRL+C to quit[0m
 * Restarting with stat
 * Debugger is active!
 * Debugger PIN: 514-421-982
127.0.0.1 - - [16/Jun/2025 22:51:46] "[35m[1mGET / HTTP/1.1[0m" 500 -
Traceback (most recent call last):
  File "/home/pablo/Desktop/Honeypot/cowrie/cowrie-env/lib/python3.13/site-packages/urllib3/connectionpool.py", line 787, in urlopen
    response = self._make_request(
    
  File "/home/pablo/Desktop/Honeypot/cowrie/cowrie-env/lib/python3.13/site-packages/urllib3/connectionpool.py", line 534, in _make_request
    response = conn.getresponse()
  File "/home/pablo/Desktop/Honeypot/cowrie/cowrie-env/lib/python3.13/site-packages/urllib3/connection.py", line 516, in getresponse
    httplib_response = super().getresponse()
  File "/usr/lib/python3.13/http/client.py", line 1430, in getresponse
    response.begin()
    ~~~~~~~~~~~~~~^^
  File "/usr/lib/python3.13/http/client.py", line 331, in begin
    version, status, reason = self._read_status()
                              ~~~~~~~~~~~~~~~~~^^
  File "/usr/lib/python3.13/http/client.py", line 300, in _read_status
    raise RemoteDisconnected("Remote end closed connection without"
    ^^^^^^^^^^^^^^^^^^^^^^^^^^^^^^^^^^^^^
http.client.RemoteDisconnected: Remote end closed connection without response

During handling of the above exception, another exception occurred:

Traceback (most recent call last):
  File "/home/pablo/Desktop/Honeypot/cowrie/cowrie-env/lib/python3.13/site-packages/elastic_transport/_node/_http_urllib3.py", line 167, in perform_request
    response = self.pool.urlopen(
    
  File "/home/pablo/Desktop/Honeypot/cowrie/cowrie-env/lib/python3.13/site-packages/urllib3/connectionpool.py", line 841, in urlopen
    retries = retries.increment(
    
  File "/home/pablo/Desktop/Honeypot/cowrie/cowrie-env/lib/python3.13/site-packages/urllib3/util/retry.py", line 449, in increment
    raise reraise(type(error), error, _stacktrace)
          ~~~~~~~^^^^^^^^^^^^^^^^^^^^^^^^^^^^^^^^^
  File "/home/pablo/Desktop/Honeypot/cowrie/cowrie-env/lib/python3.13/site-packages/urllib3/util/util.py", line 38, in reraise
    raise value.with_traceback(tb)
  File "/home/pablo/Desktop/Honeypot/cowrie/cowrie-env/lib/python3.13/site-packages/urllib3/connectionpool.py", line 787, in urlopen
    response = self._make_request(
    
  File "/home/pablo/Desktop/Honeypot/cowrie/cowrie-env/lib/python3.13/site-packages/urllib3/connectionpool.py", line 534, in _make_request
    response = conn.getresponse()
  File "/home/pablo/Desktop/Honeypot/cowrie/cowrie-env/lib/python3.13/site-packages/urllib3/connection.py", line 516, in getresponse
    httplib_response = super().getresponse()
  File "/usr/lib/python3.13/http/client.py", line 1430, in getresponse
    response.begin()
    ~~~~~~~~~~~~~~^^
  File "/usr/lib/python3.13/http/client.py", line 331, in begin
    version, status, reason = self._read_status()
                              ~~~~~~~~~~~~~~~~~^^
  File "/usr/lib/python3.13/http/client.py", line 300, in _read_status
    raise RemoteDisconnected("Remote end closed connection without"
    ^^^^^^^^^^^^^^^^^^^^^^^^^^^^^^^^^^^^^
urllib3.exceptions.ProtocolError: ('Connection aborted.', RemoteDisconnected('Remote end closed connection without response'))

The above exception was the direct cause of the following exception:

Traceback (most recent call last):
  File "/home/pablo/Desktop/Honeypot/cowrie/cowrie-env/lib/python3.13/site-packages/flask/app.py", line 1536, in __call__
    return self.wsgi_app(environ, start_response)
           ~~~~~~~~~~~~~^^^^^^^^^^^^^^^^^^^^^^^^^
  File "/home/pablo/Desktop/Honeypot/cowrie/cowrie-env/lib/python3.13/site-packages/flask/app.py", line 1514, in wsgi_app
    response = self.handle_exception(e)
  File "/home/pablo/Desktop/Honeypot/cowrie/cowrie-env/lib/python3.13/site-packages/flask/app.py", line 1511, in wsgi_app
    response = self.full_dispatch_request()
  File "/home/pablo/Desktop/Honeypot/cowrie/cowrie-env/lib/python3.13/site-packages/flask/app.py", line 919, in full_dispatch_request
    rv = self.handle_user_exception(e)
  File "/home/pablo/Desktop/Honeypot/cowrie/cowrie-env/lib/python3.13/site-packages/flask/app.py", line 917, in full_dispatch_request
    rv = self.dispatch_request()
  File "/home/pablo/Desktop/Honeypot/cowrie/cowrie-env/lib/python3.13/site-packages/flask/app.py", line 902, in dispatch_request
    return self.ensure_sync(self.view_functions[rule.endpoint])(**view_args)  # type: ignore[no-any-return]
           ~~~~~~~~~~~~~~~~~~~~~~~~~~~~~~~~~~~~~~~~~~~~~~~~~~~~^^^^^^^^^^^^^
  File "/home/pablo/Desktop/Honeypot/app.py", line 9, in dashboard
    res = es.search(index="cowrie-attacks", size=1000)
  File "/home/pablo/Desktop/Honeypot/cowrie/cowrie-env/lib/python3.13/site-packages/elasticsearch/_sync/client/utils.py", line 415, in wrapped
    return api(*args, **kwargs)
  File "/home/pablo/Desktop/Honeypot/cowrie/cowrie-env/lib/python3.13/site-packages/elasticsearch/_sync/client/__init__.py", line 4916, in search
    return self.perform_request(  # type: ignore[return-value]
    
  File "/home/pablo/Desktop/Honeypot/cowrie/cowrie-env/lib/python3.13/site-packages/elasticsearch/_sync/client/_base.py", line 271, in perform_request
    response = self._perform_request(
    
  File "/home/pablo/Desktop/Honeypot/cowrie/cowrie-env/lib/python3.13/site-packages/elasticsearch/_sync/client/_base.py", line 315, in _perform_request
    meta, resp_body = self.transport.perform_request(
    
  File "/home/pablo/Desktop/Honeypot/cowrie/cowrie-env/lib/python3.13/site-packages/elastic_transport/_transport.py", line 342, in perform_request
    resp = node.perform_request(
    
  File "/home/pablo/Desktop/Honeypot/cowrie/cowrie-env/lib/python3.13/site-packages/elastic_transport/_node/_http_urllib3.py", line 202, in perform_request
    raise err from e
elastic_transport.ConnectionError: Connection error caused by: ConnectionError(Connection error caused by: ProtocolError(('Connection aborted.', RemoteDisconnected('Remote end closed connection without response'))))
127.0.0.1 - - [16/Jun/2025 22:51:46] "[36mGET /?__debugger__=yes&cmd=resource&f=style.css HTTP/1.1[0m" 304 -
127.0.0.1 - - [16/Jun/2025 22:51:46] "[36mGET /?__debugger__=yes&cmd=resource&f=debugger.js HTTP/1.1[0m" 304 -
127.0.0.1 - - [16/Jun/2025 22:51:46] "GET /?__debugger__=yes&cmd=resource&f=console.png&s=pHuru2JaZYz6zReKICB6 HTTP/1.1" 200 -
 * Detected change in '/home/pablo/Desktop/Honeypot/alert_telegram.py', reloading
 * Restarting with stat
 * Debugger is active!
 * Debugger PIN: 514-421-982
 * Serving Flask app 'app'
 * Debug mode: on
[31m[1mWARNING: This is a development server. Do not use it in a production deployment. Use a production WSGI server instead.[0m
 * Running on http://127.0.0.1:5000
[33mPress CTRL+C to quit[0m
 * Restarting with stat
 * Debugger is active!
 * Debugger PIN: 249-565-425
 * Serving Flask app 'app'
 * Debug mode: on
[31m[1mWARNING: This is a development server. Do not use it in a production deployment. Use a production WSGI server instead.[0m
 * Running on http://127.0.0.1:5000
[33mPress CTRL+C to quit[0m
 * Restarting with stat
 * Debugger is active!
 * Debugger PIN: 249-565-425
